package _15_exceptions._06_nested_try_catch_finally;

public class ExceptionCaughtByInnerCatch {

    // Вложенный try-catch-finally с исключением, которое ПЕРЕХВАТИТ ВНУТРЕННИЙ catch

    public static void main(String[] args) {
        try {
            System.err.print(" 0");
            try {
                System.err.print(" 1");
                if (true) {throw new RuntimeException();}
                System.err.print(" 2");
            } catch (RuntimeException e) {
                System.err.print(" 3"); // ЗАХОДИМ - есть исключение
            } finally {
                System.err.print(" 4"); // заходим всегда
            }
            System.err.print(" 5");     // заходим - выполнение УЖЕ в норме
        } catch (Exception e) {
            System.err.print(" 6");     // не заходим - нет исключения, УЖЕ перехвачено
        } finally {
            System.err.print(" 7");     // заходим всегда
        }
        System.err.print(" 8");         // заходим - выполнение УЖЕ в норме
    }

    // >> 0 1 3 4 5 7 8
}
